<?xml version="1.0" ?>
<sdf version='1.8'>
  <model name="TouRobo">
  <pose>0 0 0 0 0 0</pose>

    <link name="base_footprint"/>

    <link name="base_link">
      <inertial>
        <pose>0.1 0 0 0 0 0</pose>
        <inertia>
          <ixx>4.2111447e-02</ixx>
          <ixy>0</ixy>
          <ixz>0</ixz>
          <iyy>4.2111447e-02</iyy>
          <iyz>0</iyz>
          <izz>7.5254874e-02</izz>
        </inertia>
        <mass>1.3729096e+00</mass>
      </inertial>
      <collision name="base_collision">
        <pose>0 0 0 0 0 -1.57</pose>
        <geometry>
          <mesh>
            <uri>model://TouRobo/meshes/tourobo.stl</uri>
          </mesh>
        </geometry>
      </collision>
      <visual name="base_visual">
        <pose>0 0 0 0 0 -1.57</pose>
        <geometry>
          <mesh>
            <uri>model://TouRobo/meshes/tourobo.dae</uri>
          </mesh>
        </geometry>
        <material>
          <diffuse> 0.921568627 0.925490196 0.941176471 1</diffuse>
          <ambient> 0.921568627 0.925490196 0.941176471 1</ambient>
          <specular>0.921568627 0.925490196 0.941176471 1</specular>
        </material>
      </visual>
    </link>

    <joint name="base_joint" type="fixed">
      <parent>base_footprint</parent>
      <child>base_link</child>
    </joint>

    <!-- LEFT_LIDAR -->
    <link name="left_scan">
      <pose>0 -0.2825 0.0 0 0 -1.57</pose>
      <inertial>
        <inertia>
          <ixx>0.001</ixx>
          <ixy>0</ixy>
          <ixz>0</ixz>
          <iyy>0.001</iyy>
          <iyz>0</iyz>
          <izz>0.001</izz>
        </inertia>
        <mass>0.114</mass>
      </inertial>
      <collision name="_leftlidar_sensor_collision">
        <geometry>
              <cylinder>
                  <radius>0.02</radius>
                  <length>0.05</length>
              </cylinder>
            </geometry>
      </collision>
      <visual name="left_lidar_sensor_visual">
        <geometry>
              <cylinder>
                  <radius>0.02</radius>
                  <length>0.05</length>
              </cylinder>
            </geometry>
        <material>
          <diffuse> 0.145098039 0.156862745 0.164705882 1</diffuse>
          <ambient> 0.145098039 0.156862745 0.164705882 1</ambient>
          <specular>0.145098039 0.156862745 0.164705882 1</specular>
        </material>
      </visual>
      <sensor name="left_gpu_lidar" type="gpu_lidar">
        <topic>left_scan</topic>
        <ignition_frame_id>left_scan</ignition_frame_id>
        <update_rate>40</update_rate>
        <ray>
          <scan>
            <horizontal>
              <samples>1080</samples>
              <resolution>1</resolution>
              <min_angle>-1.58</min_angle>
              <max_angle>1.58</max_angle>
            </horizontal>
          </scan>
          <range>
            <min>0.06000</min>
            <max>20.0</max>
            <resolution>0.015000</resolution>
          </range>
        </ray>
        <always_on>true</always_on>
        <visualize>true</visualize>
      </sensor>
    </link>
    <joint name="left_lidar_joint" type="fixed">
      <parent>base_link</parent>
      <child>left_scan</child>
    </joint>

    <!-- RIGHT_LIDAR -->
    <link name="right_scan">
      <pose>0 0.2825 0.0 0 0 1.57</pose>
      <inertial>
        <inertia>
          <ixx>0.001</ixx>
          <ixy>0</ixy>
          <ixz>0</ixz>
          <iyy>0.001</iyy>
          <iyz>0</iyz>
          <izz>0.001</izz>
        </inertia>
        <mass>0.114</mass>
      </inertial>
      <collision name="right_lidar_sensor_collision">
        <geometry>
              <cylinder>
                  <radius>0.02</radius>
                  <length>0.05</length>
              </cylinder>
            </geometry>
      </collision>
      <visual name="right_lidar_sensor_visual">
        <geometry>
              <cylinder>
                  <radius>0.02</radius>
                  <length>0.05</length>
              </cylinder>
            </geometry>
        <material>
          <diffuse> 0.145098039 0.156862745 0.164705882 1</diffuse>
          <ambient> 0.145098039 0.156862745 0.164705882 1</ambient>
          <specular>0.145098039 0.156862745 0.164705882 1</specular>
        </material>
      </visual>
      <sensor name="right_gpu_lidar" type="gpu_lidar">
        <topic>right_scan</topic>
        <ignition_frame_id>right_scan</ignition_frame_id>
        <update_rate>40</update_rate>
        <ray>
          <scan>
            <horizontal>
              <samples>1080</samples>
              <resolution>1</resolution>
              <min_angle>-1.58</min_angle>
              <max_angle>1.58</max_angle>
            </horizontal>
          </scan>
          <range>
            <min>0.06000</min>
            <max>20.0</max>
            <resolution>0.015000</resolution>
          </range>
        </ray>
        <always_on>true</always_on>
        <visualize>true</visualize>
      </sensor>
    </link>
    <joint name="right_lidar_joint" type="fixed">
      <parent>base_link</parent>
      <child>right_scan</child>
    </joint>

    <!-- Steer front left -->
    <link name="steer_front_left_link">
      <pose>-0.160 -0.180 0.0 0 0 0</pose>
    </link>
    <joint name="steer_front_left_joint" type="revolute">
      <parent>base_link</parent>
      <child>steer_front_left_link</child>
      <axis>
        <xyz>0 0 1</xyz>
      </axis>
    </joint>


    <!-- Wheel front left -->
    <link name="wheel_front_left_link">
      <pose>-0.160 -0.180 0  -1.57 0 0</pose>
      <inertial>
        <mass>0.1</mass>
        <inertia>
          <ixx>1.1175580e-05</ixx>
          <ixy>-4.2369783e-11</ixy>
          <ixz>-5.9381719e-09</ixz>
          <iyy>1.1192413e-05</iyy>
          <iyz>-1.4400107e-11</iyz>
          <izz>2.0712558e-05</izz>
        </inertia>
      </inertial>
      <collision name="wheel_front_left_collision">
        <geometry>
          <cylinder>
             <radius>0.055</radius>
             <length>0.025</length>
          </cylinder>
        </geometry>
      </collision>
      <visual name="wheel_front_left_visual">
          <geometry>
            <cylinder>
              <radius>0.055</radius>
              <length>0.025</length>
          </cylinder>
          </geometry>
          <material>
            <ambient>1.0 0.0 0.0 1</ambient>
            <diffuse>1.0 0.0 0.0 1</diffuse>
            <specular>1.0 0.0 0.0 1</specular>
          </material>
      </visual>
    </link>
    <joint name="wheel_front_left_joint" type="revolute">
      <parent>steer_front_left_link</parent>
      <child>wheel_front_left_link</child>
      <axis>
        <xyz>0 0 1</xyz>
      </axis>
    </joint>


    <!-- Steer front right -->
    <link name="steer_front_right_link">
      <pose>-0.160 0.180 0.0 0 0 0</pose>
    </link>
    <joint name="steer_front_right_joint" type="revolute">
      <parent>base_link</parent>
      <child>steer_front_right_link</child>
      <axis>
        <xyz>0 0 1</xyz>
      </axis>
    </joint>

    <!-- Wheel front right -->
    <link name="wheel_front_right_link">
      <pose>-0.160 0.180 0.0 -1.57 0 0</pose>
      <inertial>
        <inertia>
          <ixx>1.1175580e-05</ixx>
          <ixy>-4.2369783e-11</ixy>
          <ixz>-5.9381719e-09</ixz>
          <iyy>1.1192413e-05</iyy>
          <iyz>-1.4400107e-11</iyz>
          <izz>2.0712558e-05</izz>
        </inertia>
        <mass>0.1</mass>
      </inertial>
      <collision name="wheel_front_right_collision">
        <geometry>
          <cylinder>
             <radius>0.055</radius>
             <length>0.025</length>
          </cylinder>
        </geometry>
      </collision>
      <visual name="wheel_front_right_visual">
          <geometry>
          <cylinder>
             <radius>0.055</radius>
             <length>0.025</length>
          </cylinder>
          </geometry>
          <material>
            <ambient>1.0 0.0 0.0 1</ambient>
            <diffuse>1.0 0.0 0.0 1</diffuse>
            <specular>1.0 0.0 0.0 1</specular>
          </material>
        <material>
          <diffuse> 0.145098039 0.156862745 0.164705882 1</diffuse>
          <ambient> 0.145098039 0.156862745 0.164705882 1</ambient>
          <specular>0.145098039 0.156862745 0.164705882 1</specular>
        </material>
      </visual>
    </link>
    <joint name="wheel_front_right_joint" type="revolute">
      <parent>steer_front_right_link</parent>
      <child>wheel_front_right_link</child>
      <axis>
        <xyz>0 0 1</xyz>
      </axis>
    </joint>

      <!-- Steer back right -->
    <link name="steer_back_right_link">
      <pose>0.160 0.180 0.0 0 0 0</pose>
    </link>
    <joint name="steer_back_right_joint" type="revolute">
      <parent>base_link</parent>
      <child>steer_back_right_link</child>
      <axis>
        <xyz>0 0 1</xyz>
      </axis>
    </joint>
  
    <!-- Wheel back right -->
    <link name="wheel_back_right_link">
      <pose>0.160 0.180 0.0 -1.57 0 0</pose>
      <inertial>
        <inertia>
          <ixx>1.1175580e-05</ixx>
          <ixy>-4.2369783e-11</ixy>
          <ixz>-5.9381719e-09</ixz>
          <iyy>1.1192413e-05</iyy>
          <iyz>-1.4400107e-11</iyz>
          <izz>2.0712558e-05</izz>
        </inertia>
        <mass>0.1</mass>
      </inertial>
      <collision name="wheel_back_right_collision">
        <geometry>
          <cylinder>
             <radius>0.055</radius>
             <length>0.025</length>
          </cylinder>
        </geometry>
      </collision>
      <visual name="wheel_back_right_visual">
          <geometry>
            <cylinder>
               <radius>0.055</radius>
               <length>0.025</length>
            </cylinder>
          </geometry>
          <material>
            <ambient>1.0 0.0 0.0 1</ambient>
            <diffuse>1.0 0.0 0.0 1</diffuse>
            <specular>1.0 0.0 0.0 1</specular>
          </material>
        <material>
          <diffuse> 0.145098039 0.156862745 0.164705882 1</diffuse>
          <ambient> 0.145098039 0.156862745 0.164705882 1</ambient>
          <specular>0.145098039 0.156862745 0.164705882 1</specular>
        </material>
      </visual>
    </link>
    <joint name="wheel_back_right_joint" type="revolute">
      <parent>steer_back_right_link</parent>
      <child>wheel_back_right_link</child>
      <axis>
        <xyz>0 0 1</xyz>
      </axis>
    </joint>
  
    <!-- Steer back left -->
    <link name="steer_back_left_link">
      <pose>0.160 -0.180 0.0 0 0 0</pose>
    </link>
    <joint name="steer_back_left_joint" type="revolute">
      <parent>base_link</parent>
      <child>steer_back_left_link</child>
      <axis>
        <xyz>0 0 1</xyz>
      </axis>
    </joint>

    <!-- Wheel back left -->
    <link name="wheel_back_left_link">
      <pose>0.160 -0.180 0.0 -1.57 0 0</pose>
      <inertial>
        <inertia>
          <ixx>1.1175580e-05</ixx>
          <ixy>-4.2369783e-11</ixy>
          <ixz>-5.9381719e-09</ixz>
          <iyy>1.1192413e-05</iyy>
          <iyz>-1.4400107e-11</iyz>
          <izz>2.0712558e-05</izz>
        </inertia>
        <mass>0.1</mass>
      </inertial>
      <collision name="wheel_back_left_collision">
        <geometry>
          <cylinder>
             <radius>0.055</radius>
             <length>0.025</length>
          </cylinder>
        </geometry>
      </collision>
      <visual name="wheel_back_left_visual">
          <geometry>
            <cylinder>
               <radius>0.055</radius>
               <length>0.025</length>
            </cylinder>
          </geometry>
          <material>
            <ambient>1.0 0.0 0.0 1</ambient>
            <diffuse>1.0 0.0 0.0 1</diffuse>
            <specular>1.0 0.0 0.0 1</specular>
          </material>
        <material>
          <diffuse> 0.145098039 0.156862745 0.164705882 1</diffuse>
          <ambient> 0.145098039 0.156862745 0.164705882 1</ambient>
          <specular>0.145098039 0.156862745 0.164705882 1</specular>
        </material>
      </visual>
    </link>
    <joint name="wheel_back_left_joint" type="revolute">
      <parent>steer_back_left_link</parent>
      <child>wheel_back_left_link</child>
      <axis>
        <xyz>0 0 1</xyz>
      </axis>
    </joint>

    
    <!-- Differential drive -->
    <!-- <plugin filename="libignition-gazebo-diff-drive-system.so" 
      name="ignition::gazebo::systems::DiffDrive">
      <left_joint>wheel_left_joint</left_joint>
      <right_joint>wheel_right_joint</right_joint>
      <wheel_separation>0.19</wheel_separation>
      <wheel_radius>0.033</wheel_radius>
      <topic>cmd_vel</topic>
    </plugin> -->

    <!-- steer drive -->
    <plugin filename="libSteerControler" name="iginition_plugin_steer::SteerControler">
      <steer1_joint>steer_front_right_joint</steer1_joint>
      <steer2_joint>steer_front_left_joint</steer2_joint>
      <steer3_joint>steer_back_left_joint</steer3_joint>
      <steer4_joint>steer_back_right_joint</steer4_joint>
      <wheel1_joint>wheel_front_right_joint</wheel1_joint>
      <wheel2_joint>wheel_front_left_joint</wheel2_joint>
      <wheel3_joint>wheel_back_left_joint</wheel3_joint>
      <wheel4_joint>wheel_back_right_joint</wheel4_joint>
    </plugin>

    <!-- Joint state publisher -->
    <plugin filename="libignition-gazebo-joint-state-publisher-system.so" 
      name="ignition::gazebo::systems::JointStatePublisher">
      <topic>joint_states</topic>
    </plugin>

    <!-- Global odometer -->
    <plugin
      filename="ignition-gazebo-odometry-publisher-system"
      name="ignition::gazebo::systems::OdometryPublisher">
      <odom_publish_frequency>50</odom_publish_frequency>
      <odom_topic>/odom</odom_topic>
      <odom_frame>odom</odom_frame>
      <robot_base_frame>base_footprint</robot_base_frame>
      <tf_topic>/odom/tf</tf_topic>
    </plugin>

  </model>
</sdf>